<?xml version="1.0"?>
<robot name="meldog_simple_core"
    xmlns:xacro="http://www.ros.org/wiki/xacro">

    <xacro:include filename="base_properties.urdf.xacro" />

    <link name="upper_limb_link">
        <visual>
            <geometry>
                <mesh filename="package://meldog_simple_twin/meshes/visual/${upper_limb_vis_stl_name}" 
                      scale="0.001 0.001 0.001" />
            </geometry>
            <origin xyz="0 0 0" rpy="0 0 0"/>
        </visual>

        <collision>
            <geometry>
                <mesh filename="package://meldog_simple_twin/meshes/collision/${upper_limb_coll_stl_name}" 
                      scale="0.001 0.001 0.001" />
            </geometry>
            <origin xyz="0 0 0" rpy="0 0 0" />
        </collision>

        <inertial>
            <mass value="${upper_limb_mass}" />
            <origin xyz="${upper_limb_cm_x} ${upper_limb_cm_y} ${upper_limb_cm_z}" rpy="0 0 0" />
            <inertia ixx="${upper_limb_ixx}" ixy="${upper_limb_ixy}" ixz="${upper_limb_ixz}" 
                                             iyy="${upper_limb_iyy}" iyz="${upper_limb_iyz}" 
                                                                     izz="${upper_limb_izz}" />
        </inertial>

    </link>

    <link name="lower_limb_link">
        <visual>
            <geometry>
                <mesh filename="package://meldog_simple_twin/meshes/visual/${lower_limb_vis_stl_name}" 
                      scale="0.001 0.001 0.001" />
            </geometry>
            <origin xyz="0 0 0" rpy="0 0 0"/>
        </visual>

        <collision>
            <geometry>
                <mesh filename="package://meldog_simple_twin/meshes/collision/${lower_limb_coll_stl_name}" 
                      scale="0.001 0.001 0.001" />
            </geometry>
            <origin xyz="0 0 0" rpy="0 0 0" />
        </collision>

        <inertial>
            <mass value="${lower_limb_mass}" />
            <origin xyz="${lower_limb_cm_x} ${lower_limb_cm_y} ${lower_limb_cm_z}" rpy="0 0 0" />
            <inertia ixx="${lower_limb_ixx}" ixy="${lower_limb_ixy}" ixz="${lower_limb_ixz}" 
                                             iyy="${lower_limb_iyy}" iyz="${lower_limb_iyz}" 
                                                                     izz="${lower_limb_izz}" />
        </inertial>

    </link>

    <link name="foot_link" />

    <link name="leg_body_link">
        <visual>
            <geometry>
                <mesh filename="package://meldog_simple_twin/meshes/visual/${leg_body_vis_stl_name}" 
                      scale="0.001 0.001 0.001" />
            </geometry>
            <origin xyz="0 0 0" rpy="0 0 0" />
        </visual>

        <collision>
            <geometry>
                <mesh filename="package://meldog_simple_twin/meshes/collision/${leg_body_coll_stl_name}" 
                      scale="0.001 0.001 0.001" />
            </geometry>
            <origin xyz="0 0 0" rpy="0 0 0" />
        </collision>

        <inertial>
            <mass value="${leg_body_mass}" />
            <origin xyz="${leg_body_cm_x} ${leg_body_cm_y} ${leg_body_cm_z}" rpy="0 0 0" />
            <inertia ixx="${leg_body_ixx}" ixy="${leg_body_ixy}" ixz="${leg_body_ixz}" 
                                           iyy="${leg_body_iyy}" iyz="${leg_body_iyz}" 
                                                                 izz="${leg_body_izz}" />
        </inertial>

    </link>

    <joint name="leg_body_upper_limb_joint" type="revolute">
        <parent link="leg_body_link" /> 
        <child link="upper_limb_link" />
        <origin xyz="${leg_body_upper_limb_x}
                     ${leg_body_upper_limb_y}
                     ${leg_body_upper_limb_z}" 
                rpy="0 0 0" />
        <limit lower="${leg_body_upper_limb_lower_limit/180.0*pi}" 
               upper="${leg_body_upper_limb_upper_limit/180.0*pi}" 
               effort="${leg_body_upper_limb_effort}" 
               velocity="${leg_body_upper_limb_velocity}" />
        <axis xyz="0 1 0" />
    </joint>

    <joint name="upper_limb_lower_limb_joint" type="revolute">
        <parent link="upper_limb_link" />
        <child link="lower_limb_link" />
        <origin xyz="0 0 ${-upper_limb_length}" rpy="0 0 0" />
        <limit lower="${upper_limb_lower_limb_lower_limit/180.0*pi}" 
               upper="${upper_limb_lower_limb_upper_limit/180.0*pi}" 
               effort="${upper_limb_lower_limb_effort}" 
               velocity="${upper_limb_lower_limb_velocity}" />
        <axis xyz="0 1 0" />
    </joint>

    <joint name="lower_limb_foot_joint" type="fixed">
        <parent link="lower_limb_link" />
        <child link="foot_link" />
        <origin xyz="0 0 ${-lower_limb_length_to_foot}" rpy="0 0 0" />
    </joint>

</robot>