<?xml version="1.0"?>
<robot name="meldog_simple_core" xmlns:xacro="http://www.ros.org/wiki/xacro">

    <xacro:include filename="base_properties.urdf.xacro" />
    <xacro:include filename="macros/macros.urdf.xacro" />

    <xacro:link_macro 
        name="upper_limb_link" 
        vis_name="${upper_limb_vis_stl_name}" 
        coll_name="${upper_limb_coll_stl_name}" 

        m="${upper_limb_mass}" 
        cm_x="${upper_limb_cm_x}" 
        cm_y="${upper_limb_cm_y}" 
        cm_z="${upper_limb_cm_z}"

        ixx="${upper_limb_ixx}" ixy="${upper_limb_ixy}" ixz="${upper_limb_ixz}" 
                                iyy="${upper_limb_iyy}" iyz="${upper_limb_iyz}" 
                                                        izz="${upper_limb_izz}"/>

    <xacro:link_macro 
        name="lower_limb_link" 
        vis_name="${lower_limb_vis_stl_name}" 
        coll_name="${lower_limb_coll_stl_name}" 

        m="${lower_limb_mass}" 
        cm_x="${lower_limb_cm_x}" 
        cm_y="${lower_limb_cm_y}" 
        cm_z="${lower_limb_cm_z}"

        ixx="${lower_limb_ixx}" ixy="${lower_limb_ixy}" ixz="${lower_limb_ixz}" 
                                iyy="${lower_limb_iyy}" iyz="${lower_limb_iyz}" 
                                                        izz="${lower_limb_izz}"/>



    <link name="foot_link" />

    <xacro:link_macro 
        name="hip_link" 
        vis_name="${hip_vis_stl_name}" 
        coll_name="${hip_coll_stl_name}" 

        m="${hip_mass}" 
        cm_x="${hip_cm_x}" 
        cm_y="${hip_cm_y}" 
        cm_z="${hip_cm_z}"

        ixx="${hip_ixx}" ixy="${hip_ixy}" ixz="${hip_ixz}" 
                         iyy="${hip_iyy}" iyz="${hip_iyz}" 
                                          izz="${hip_izz}"/>

    <joint name="hip_upper_limb_joint" type="revolute">
        <parent link="hip_link" /> 
        <child link="upper_limb_link" />
        <origin xyz="${hip_upper_limb_x}
                     ${hip_upper_limb_y}
                     ${hip_upper_limb_z}" 
                rpy="0 0 0" />
        <limit lower="${hip_upper_limb_lower_limit/180.0*pi}" 
               upper="${hip_upper_limb_upper_limit/180.0*pi}" 
               effort="${hip_upper_limb_effort}" 
               velocity="${hip_upper_limb_velocity}" />
        <axis xyz="0 1 0" />
    </joint>

    <joint name="upper_limb_lower_limb_joint" type="revolute">
        <parent link="upper_limb_link" />
        <child link="lower_limb_link" />
        <origin xyz="0 0 ${-upper_limb_length}" rpy="0 0 0" />
        <limit lower="${upper_limb_lower_limb_lower_limit/180.0*pi}" 
               upper="${upper_limb_lower_limb_upper_limit/180.0*pi}" 
               effort="${upper_limb_lower_limb_effort}" 
               velocity="${upper_limb_lower_limb_velocity}" />
        <axis xyz="0 1 0" />
    </joint>

    <joint name="lower_limb_foot_joint" type="fixed">
        <parent link="lower_limb_link" />
        <child link="foot_link" />
        <origin xyz="0 0 ${-lower_limb_length_to_foot}" rpy="0 0 0" />
    </joint>

</robot>